Workbook
Name Depreciação: #REF!
Name Depreciação: #REF!
Name Depreciação: #REF!
Name Despesas_com_Marketing: #REF!
Name Despesas_com_Produtos: #REF!
Name Despesas_com_RH: #REF!
Name Despesas_com_Serviços: #REF!
Name Despesas_Não_Operacionais: #REF!
Name Despesas_Operacionais: #REF!
Name Impostos: #REF!
Name Investimentos: #REF!
Name Receitas_com_Produtos: #REF!
Name Receitas_Com_Serviços: #REF!
Name Receitas_Não_Operacionais: #REF!
Name Sal: [1]Cad3!$B$5:$B$14
Name Sal: [2]Cad3!$B$5:$B$14

Sheet MENU
E2: RESOLUÇÃO Nº 1/17 DE 5 DE JANEIRO Prestações de Contas dos Órgãos Autónomos, Sector Empresarial Público e demais Serviços e Entidades do sector Produtivo regidos pelo Plano Geral de Contabilidade.
C3: ENTIDADE:
C4: PERÍODO:
C6: 1.0 | D6: PLANO DE CONTAS E BALANCETE | E6: O Plano de Contas serve de guia para o preenchimento do Balancete, pois o mesmo está estruturado conforme a elaboração e apresentação do Balanço Patrimonial e da Demonstração de Resultados, de acordo com o estabelecido no Plano Geral de Contabilidade, aprovado pelo Decreto nº 82/2001, de 16 de Novembro, actualizado pelo Decreto Presidencial nº 180/19, de 24 de Maio, que regula a implementação do IVA.
C8: 2.0 | D8: BALANÇO PATRIMONIAL | E8: Registar os valores referentes ao Balanço Patrimonial, classificando-os em Activos (Não Corrente e Corrente), Passivo (Não Corrente e Corrente) e o Capital Próprio.
C10: 3.0 | D10: DEMONSTRAÇÃO DO RESULTADO DO EXERCÍCIO | E10: Registar os valores referentes ao resultado do exercício, classificando-os em Proveitos (Receitas) e Custos (Despesas).
C12: 4.0 | D12: GRÁFICOS DEMONSTRAÇÕES CONTÁBEIS | E12: Apresentação dos Gráficos do Balanço Patrimonial e Demonstração do Resultado do Exercício para melhor visualização
C14: 4.0 | D14: INDICADORES FINANCEIROS | E14: Análise dos principais indicadores financeiros com base nas demonstrações financeiras
C16: 5.0 | D16: AVALIAÇÃO DA CONTA | E16: Avaliação Final da Conta.
C18: 6.0 | D18: RELATÓRIO COMPLETO | E18: Relatório Completo das Demonstrações Financeiras e Indicadores Financeiros para impressão.

Sheet Plano Contas
A3: NOTA | B3: CÓDIGO | C3: CONTAS DO BALANÇO PATRIMONIAL | D3: CONTA DO PGC | E3: NATUREZA DA CONTA
B6: 1 | C6: ACTIVO
B7: 1.1 | C7: Activos não Correntes | D7: 1
B8: 1.1.1 | C8: Imobilizações corpóreas | D8: 11
B9: 1.1.1.1 | C9: Terrenos e recursos naturais | D9: 11.1 | E9: Devedora
B10: 1.1.1.2 | C10: Edifícios e outras construções | D10: 11.2 | E10: Devedora
B11: 1.1.1.3 | C11: Equipamento básico | D11: 11.3 | E11: Devedora
B12: 1.1.1.4 | C12: Equipamento de transporte | D12: 11.4 | E12: Devedora
B13: 1.1.1.5 | C13: Equipamento administrativo | D13: 11.5 | E13: Devedora
B14: 1.1.1.6 | C14: Taras e vasilhames | D14: 11.6 | E14: Devedora
B15: 1.1.1.7 | C15: Outras imobilizações corpóreas | D15: 11.9 | E15: Devedora
B16: 1.1.1.8 | C16: Imobilizado em curso | D16: 14.1 | E16: Devedora
B17: 1.1.1.9 | C17: Adiantamentos por conta de imobilizações corpóres | D17: 14.7 | E17: Devedora
B18: 1.1.1.10 | C18: Amortizações acumuladas - Imobilizações corpóreas | D18: 18.1 | E18: Credora
B19: 1.1.2 | C19: Imobilizações incorpóreas | D19: 12
B20: 1.1.2.1 | C20: Trespasses | D20: 12.1 | E20: Devedora
B21: 1.1.2.2 | C21: Despesas de desenvolvimento | D21: 12.2 | E21: Devedora
B22: 1.1.2.3 | C22: Propriedade industrial e outros direitos e contratos | D22: 12.3 | E22: Devedora
B23: 1.1.2.4 | C23: Despesas de constituição | D23: 12.4 | E23: Devedora
B24: 1.1.2.5 | C24: Outras imobilizações incorpóreas | D24: 12.9 | E24: Devedora
B25: 1.1.2.6 | C25: Adiantamentos por conta de imobilizado incorpóreo | D25: 14.8 | E25: Devedora
B26: 1.1.2.7 | C26: Amortizações acumuladas - Imobilizações incorpóreas | D26: 18.2 | E26: Credora
B27: 1.1.3 | C27: Investimentos em subsidiárias e associadas | D27: 13
B28: 1.1.3.1 | C28: Empresas subsidiárias | D28: 13.1 | E28: Devedora
B29: 1.1.3.1.1 | C29: Partes de capital | D29: 13.1.1 | E29: Devedora
B30: 1.1.3.1.2 | C30: Obrigações e outros títulos de participaçãpo | D30: 13.1.2 | E30: Devedora
B31: 1.1.3.1.3 | C31: Empréstimos | D31: 13.1.3 | E31: Devedora
B32: 1.1.3.1.4 | C32: Adiantamentos por conta | D32: 13.1.4 | E32: Devedora
B33: 1.1.3.2 | C33: Empresas associadas | D33: 13.2 | E33: Devedora
B34: 1.1.3.2.1 | C34: Partes de capital | D34: 13.2.1 | E34: Devedora
B35: 1.1.3.2.2 | C35: Obrigações e outros títulos de participaçãpo | D35: 13.2.2 | E35: Devedora
B36: 1.1.3.2.3 | C36: Empréstimos | D36: 13.2.3 | E36: Devedora
B37: 1.1.3.2.4 | C37: Adiantamentos por conta | D37: 13.2.4 | E37: Devedora
B38: 1.1.4 | C38: Outros activos financeiros
B39: 1.1.4.1 | C39: Investimentos em outras empresas | D39: 13.3 | E39: Devedora
B40: 1.1.4.2 | C40: Investimentos em imóveis | D40: 13.4 | E40: Devedora
B41: 1.1.4.3 | C41: Fundos | D41: 13.5 | E41: Devedora
B42: 1.1.4.4 | C42: Outros investimentos financeiros | D42: 13.9 | E42: Devedora
B43: 1.1.4.5 | C43: Adiantamento por conta de investimentos financeiros | D43: 14.9 | E43: Devedora
B44: 1.1.4.6 | C44: Amortizações acumuladas - Investimentos financeiros em imóveis | D44: 18.3 | E44: Credora
...

Sheet Balancete
B3: BALANCETE INICIAL E FINAL - ANO DE 202---
B4: Valor em Kwanzas
B5: Conta | C5: Designação da Conta | D5: Movim. Débito | E5: Movim. Crédito | F5: Saldo do Ano Corrente | G5: Saldo do Ano Anterior | H5: Coluna1
B6: 1 | C6: Meios Fixos e Investimentos | D6: =D7+D35+D43+D60+D68+D86 -> 9.6280248e+09 | E6: =E7+E35+E43+E60+E68+E86 -> 6.1830743e+09 | F6: =IF(D6>0,D6-E6,D6-E6) -> 3.4449505e+09 | G6: =G7+G35+G43+G60+G68+G86 -> 0
B7: 11 | C7: Imobilizações Corpóreas | D7: =D8+D13+D17+D21+D24+D29+D32 -> 9.2928895e+09 | E7: =E8+E13+E17+E21+E24+E29+E32 -> 53258116 | F7: =IF(D7>=E7,D7-E7,D7-E7) -> 9.2396314e+09 | G7: =G8+G13+G17+G21+G24+G29+G32 -> 0
B8: 111 | C8: Terrenos e recursos naturais | D8: =SUM(D9:D12) -> 0 | E8: =SUM(E9:E12) -> 0 | F8: =IF(D8>=E8,D8-E8,D8-E8) -> 0 | G8: =SUM(G9:G12) -> 0
B9: 1111 | C9: Terrenos em bruto | F9: =IF(D9>=E9,D9-E9,D9-E9) -> 0
B10: 1112 | C10: Terrenos com arranjos | F10: =IF(D10>=E10,D10-E10,D10-E10) -> 0
B11: 1113 | C11: Subsolos | F11: =IF(D11>=E11,D11-E11,D11-E11) -> 0
B12: 1114 | C12: Terrenos com edíficios | F12: =IF(D12>=E12,D12-E12,D12-E12) -> 0
B13: 112 | C13: Edíficios e outras construções | D13: =SUM(D14:D16) -> 4.3974829e+09 | E13: =SUM(E14:E16) -> 0 | F13: =IF(D13>=E13,D13-E13,D13-E13) -> 4.3974829e+09 | G13: =SUM(G14:G16) -> 0
B14: 1121 | C14: Edíficos | D14: 4.3974829e+09 | E14: 0 | F14: =IF(D14>=E14,D14-E14,D14-E14) -> 4.3974829e+09
B15: 1122 | C15: Outras construções | F15: =IF(D15>=E15,D15-E15,D15-E15) -> 0
B16: 1123 | C16: Instalações | F16: =IF(D16>=E16,D16-E16,D16-E16) -> 0
B17: 113 | C17: Equipamento básico | D17: =SUM(D18:D20) -> 2.987458e+09 | E17: =SUM(E18:E20) -> 0 | F17: =IF(D17>=E17,D17-E17,D17-E17) -> 2.987458e+09 | G17: =SUM(G18:G20) -> 0
B18: 1131 | C18: Material industrial | D18: 2.987458e+09 | F18: =IF(D18>=E18,D18-E18,D18-E18) -> 2.987458e+09
B19: 1132 | C19: Ferramentas industriais | F19: =IF(D19>=E19,D19-E19,D19-E19) -> 0
B20: 1133 | C20: Melhoramentos em equipamentos básicos | F20: =IF(D20>=E20,D20-E20,D20-E20) -> 0
B21: 114 | C21: Equipamento de carga e transporte | D21: =SUM(D22:D23) -> 7.8204229e+08 | E21: =SUM(E22:E23) -> 0 | F21: =IF(D21>=E21,D21-E21,D21-E21) -> 7.8204229e+08 | G21: =SUM(G22:G23) -> 0
B22: 1141 | C22: Veículos pesados | D22: 7.8204229e+08 | F22: =IF(D22>=E22,D22-E22,D22-E22) -> 7.8204229e+08
B23: 1142 | C23: Veículos mistos e ligeiros | F23: =IF(D23>=E23,D23-E23,D23-E23) -> 0
B24: 115 | C24: Equipamento administrativo | D24: =SUM(D25:D28) -> 6.3292314e+08 | E24: =SUM(E25:E28) -> 0 | F24: =IF(D24>=E24,D24-E24,D24-E24) -> 6.3292314e+08 | G24: =SUM(G25:G28) -> 0
B25: 1151 | C25: Equipamento informático | D25: 6.3292314e+08 | F25: =IF(D25>=E25,D25-E25,D25-E25) -> 6.3292314e+08
B26: 1152 | C26: Equipamento Social | F26: =IF(D26>=E26,D26-E26,D26-E26) -> 0
B27: 1153 | C27: Mobiliario | F27: =IF(D27>=E27,D27-E27,D27-E27) -> 0
B28: 1154 | C28: Outros equipamentos administrativos | F28: =IF(D28>=E28,D28-E28,D28-E28) -> 0
B29: 116 | C29: Taras e vasilhame | D29: =D30+D31 -> 0 | E29: =E30+E31 -> 0 | F29: =IF(D29>=E29,D29-E29,D29-E29) -> 0 | G29: =G30+G31 -> 0
B30: 1161 | C30: Embalagens retornáveis | F30: =IF(D30>=E30,D30-E30,D30-E30) -> 0
B31: 1162 | C31: Outras taras e outras embalagens | F31: =IF(D31>=E31,D31-E31,D31-E31) -> 0
B32: 119 | C32: Outras imobilizações corpóreas | D32: =SUM(D33:D34) -> 4.9298322e+08 | E32: =SUM(E33:E34) -> 53258116 | F32: =IF(D32>=E32,D32-E32,D32-E32) -> 4.397251e+08 | G32: =SUM(G33:G34) -> 0
B33: 1191 | C33: Outras inst. e máquinas de uso especifico | D33: 4.9298322e+08 | E33: 53258116 | F33: =IF(D33>=E33,D33-E33,D33-E33) -> 4.397251e+08
B34: 1192 | C34: Outras imobilizações | F34: =IF(D34>=E34,D34-E34,D34-E34) -> 0
B35: 12 | C35: Imobilizações Incorpóreas | D35: =D36+D37+D38+D41+D42 -> 2.8187711e+08 | E35: =E36+E37+E38+E41+E42 -> 0 | F35: =IF(D35>=E35,D35-E35,D35-E35) -> 2.8187711e+08 | G35: =G36+G37+G38+G41+G42 -> 0
B36: 121 | C36: Trespasses | F36: =IF(D36>=E36,D36-E36,D36-E36) -> 0
B37: 122 | C37: Despesas de investigação e desenvolvimento | D37: 1.3370129e+08 | F37: =IF(D37>=E37,D37-E37,D37-E37) -> 1.3370129e+08
B38: 123 | C38: Propriedade industrial e outros direitos e contratos | D38: =SUM(D39:D40) -> 4887501 | E38: =SUM(E39:E40) -> 0 | F38: =IF(D38>=E38,D38-E38,D38-E38) -> 4887501 | G38: =SUM(G39:G40) -> 0
B39: 1231 | C39: Licenças informáticas diversas | F39: =IF(D39>=E39,D39-E39,D39-E39) -> 0
B40: 1232 | C40: Propriedade industrial e outros | D40: 4887501 | F40: =IF(D40>=E40,D40-E40,D40-E40) -> 4887501
B41: 124 | C41: Despesas de constituição | F41: =IF(D41>=E41,D41-E41,D41-E41) -> 0
B42: 129 | C42: Outras imobilizações incorpóreas | D42: 1.4328832e+08 | F42: =IF(D42>=E42,D42-E42,D42-E42) -> 1.4328832e+08
...

Sheet Activos Não Correntes
B2: OBS: NÃO PREENCHER OS CAMPOS EM AZUL. PREENCHIMENTO AUTOMÁTICO.
E3: Ano Corrente | G3: Ano Anterior | L3: Ano Corrente | N3: Ano Anterior
C4: 1.1 | D4: Activos Não Correntes | E4: =IF(ISERROR($E$5+$E$16+$E$26+$E$30+$E$38+$E$45+$E$55),"",$E$5+$E$16+$E$26+$E$30+$E$38+$E$45+$E$55) -> 3.4449505e+09 | G4: =IF(ISERROR($G$5+$G$16+$G$26+$G$30+$G$38+$G$45+$G$55),"",$G$5+$G$16+$G$26+$G$30+$G$38+$G$45+$G$55) -> 0 | J4: =C4 -> 1.1 | K4: Activos Não Correntes - Total
C5: 1.1.1 | D5: Imobilizações corpóreas | E5: =IF(ISERROR(SUM(E6:E15)),"",SUM(E6:E15)) -> 3.4238736e+09 | G5: =IF(ISERROR(SUM(G6:G15)),"",SUM(G6:G15)) -> 0 | J5: =C5 -> 1.1.1 | K5: =D5 -> Imobilizações corpóreas | L5: =IF(ISERROR($E$5),"",$E$5) -> 3.4238736e+09 | M5: =IF(ISERROR(L5/$P$5),"",L5/$P$5) -> 0.9938818 | N5: =IF(ISERROR($G$5),"",$G$5) -> 0 | O5: =IF(ISERROR(N5/$Q$5),"",N5/$Q$5) | P5: =IF(ISERROR(SUM($L$5:$L$13)),"",SUM($L$5:$L$13)) -> 3.4449505e+09 | Q5: =IF(ISERROR(SUM($N$5:$N$13)),"",SUM($N$5:$N$13)) -> 0
C6: 1.1.1.1 | D6: Terrenos e recursos naturais | E6: =Balancete!F8 -> 0 | F6: =IF(ISERROR(E6/$E$5),"",E6/$E$5) -> 0 | G6: =Balancete!G8 -> 0 | H6: =IF(ISERROR(G6/$G$5),"",G6/$G$5) | J6: =C16 -> 1.1.2 | K6: =D16 -> Imobilizações incorpóreas | L6: =IF(ISERROR($E$16),"",$E$16) -> 21076889 | M6: =IF(ISERROR(L6/$P$5),"",L6/$P$5) -> 0.0061181981 | N6: =IF(ISERROR($G$16),"",$G$16) -> 0 | O6: =IF(ISERROR(N6/$Q$5),"",N6/$Q$5)
C7: 1.1.1.2 | D7: Edifícios e outras construções | E7: =Balancete!F13 -> 4.3974829e+09 | F7: =IF(ISERROR(E7/$E$5),"",E7/$E$5) -> 1.284359 | G7: =Balancete!G13 -> 0 | H7: =IF(ISERROR(G7/$G$5),"",G7/$G$5) | J7: =C26 -> 1.1.3 | K7: =D26 -> Investimentos em Subsidiárias e Associadas | L7: =IF(ISERROR($E$26),"",$E$26) -> 0 | M7: =IF(ISERROR(L7/$P$5),"",L7/$P$5) -> 0 | N7: =IF(ISERROR($G$26),"",$G$26) -> 0 | O7: =IF(ISERROR(N7/$Q$5),"",N7/$Q$5)
C8: 1.1.1.3 | D8: Equipamento básico | E8: =Balancete!F17 -> 2.987458e+09 | F8: =IF(ISERROR(E8/$E$5),"",E8/$E$5) -> 0.87253747 | G8: =Balancete!G17 -> 0 | H8: =IF(ISERROR(G8/$G$5),"",G8/$G$5) | J8: =C30 -> 1.1.4 | K8: =D30 -> Outros Activos Financeiros | L8: =IF(ISERROR($E$30),"",$E$30) -> 0 | M8: =IF(ISERROR(L8/$P$5),"",L8/$P$5) -> 0 | N8: =IF(ISERROR($G$30),"",$G$30) -> 0 | O8: =IF(ISERROR(N8/$Q$5),"",N8/$Q$5)
C9: 1.1.1.4 | D9: Equipamento de transporte | E9: =Balancete!F21 -> 7.8204229e+08 | F9: =IF(ISERROR(E9/$E$5),"",E9/$E$5) -> 0.22840864 | G9: =Balancete!G21 -> 0 | H9: =IF(ISERROR(G9/$G$5),"",G9/$G$5) | J9: =C38 -> 1.1.5 | K9: =D38 -> Provisões para Investimentos Financeiros | L9: =IF(ISERROR($E$38),"",$E$38) -> 0 | M9: =IF(ISERROR(L9/$P$5),"",L9/$P$5) -> 0 | N9: =IF(ISERROR($G$38),"",$G$38) -> 0 | O9: =IF(ISERROR(N9/$Q$5),"",N9/$Q$5)
C10: 1.1.1.5 | D10: Equipamento administrativo | E10: =Balancete!F24 -> 6.3292314e+08 | F10: =IF(ISERROR(E10/$E$5),"",E10/$E$5) -> 0.18485587 | G10: =Balancete!G24 -> 0 | H10: =IF(ISERROR(G10/$G$5),"",G10/$G$5) | J10: =C45 -> 1.1.6 | K10: =D45 -> Outros Activos não Correntes | L10: =IF(ISERROR($E$45),"",$E$45) -> 0 | M10: =IF(ISERROR(L10/$P$5),"",L10/$P$5) -> 0 | N10: =IF(ISERROR($G$45),"",$G$45) -> 0 | O10: =IF(ISERROR(N10/$Q$5),"",N10/$Q$5)
C11: 1.1.1.6 | D11: Outras imobilizações corpóreas | E11: =Balancete!F32 -> 4.397251e+08 | F11: =IF(ISERROR(E11/$E$5),"",E11/$E$5) -> 0.12842913 | G11: =Balancete!G32 -> 0 | H11: =IF(ISERROR(G11/$G$5),"",G11/$G$5) | L11: =IF(ISERROR(E55),"",E55) -> 0 | M11: =IF(ISERROR(L11/$P$5),"",L11/$P$5) -> 0 | N11: =IF(ISERROR($G$55),"",$G$55) -> 0 | O11: =IF(ISERROR(N11/$Q$5),"",N11/$Q$5)
C12: 1.1.1.7 | D12: Taras e vasilhames | E12: =Balancete!F29 -> 0 | F12: =IF(ISERROR(E12/$E$5),"",E12/$E$5) -> 0 | G12: =Balancete!G29 -> 0 | H12: =IF(ISERROR(G12/$G$5),"",G12/$G$5)
C13: 1.1.1.8 | D13: Imobilizado em curso | E13: =Balancete!F61 -> 0 | F13: =IF(ISERROR(E13/$E$5),"",E13/$E$5) -> 0 | G13: =Balancete!G61 -> 0 | H13: =IF(ISERROR(G13/$G$5),"",G13/$G$5)
C14: 1.1.1.9 | D14: Adiantamentos por conta de imobilizações corpóres | E14: =Balancete!F65 -> 0 | G14: =Balancete!F65 -> 0 | H14: =IF(ISERROR(G14/$G$5),"",G14/$G$5) | J14: Direitos Realizáveis a Longo Prazo
C15: 1.1.1.10 | D15: Amortizações acumuladas | E15: =Balancete!F69 -> -5.8157579e+09 | F15: =IF(ISERROR(E15/$E$5),"",E15/$E$5) -> -1.6985901 | G15: =Balancete!G69 -> 0 | H15: =IF(ISERROR(G15/$G$5),"",G15/$G$5) | J15: =C5 -> 1.1.1 | K15: =D5 -> Imobilizações corpóreas | L15: =IF(ISERROR($E$5),"",$E$5) -> 3.4238736e+09 | M15: =IF(ISERROR(L15/$L$21),"",L15/$L$21) -> 0.9938818 | N15: =IF(ISERROR($G$5),"",$G$5) -> 0 | O15: =IF(ISERROR(N15/$N$21),"",N15/$N$21)
C16: 1.1.2 | D16: Imobilizações incorpóreas | E16: =IF(ISERROR(SUM(E17:E25)),"",SUM(E17:E25)) -> 21076889 | G16: =IF(ISERROR(SUM(G17:G25)),"",SUM(G17:G25)) -> 0 | J16: =C16 -> 1.1.2 | K16: =D16 -> Imobilizações incorpóreas | L16: =IF(ISERROR($E$16),"",$E$16) -> 21076889 | M16: =IF(ISERROR(L16/$L$21),"",L16/$L$21) -> 0.0061181981 | N16: =IF(ISERROR($G$16),"",$G$16) -> 0 | O16: =IF(ISERROR(N16/$N$21),"",N16/$N$21)
C17: 1.1.2.1 | D17: Trespasses | E17: =Balancete!F36 -> 0 | F17: =IF(ISERROR(E17/$E$16),"",E17/$E$16) -> 0 | G17: =Balancete!G36 -> 0 | J17: =C26 -> 1.1.3 | K17: =D26 -> Investimentos em Subsidiárias e Associadas | L17: =IF(ISERROR($E$26),"",$E$26) -> 0 | M17: =IF(ISERROR(L17/$L$21),"",L17/$L$21) -> 0 | N17: =IF(ISERROR($G$26),"",$G$26) -> 0 | O17: =IF(ISERROR(N17/$N$21),"",N17/$N$21)
C18: 1.1.2.2 | D18: Despesas de investigação e desenvolvimento | E18: =Balancete!F37 -> 1.3370129e+08 | F18: =IF(ISERROR(E18/$E$16),"",E18/$E$16) -> 6.343502 | G18: =Balancete!G37 -> 0 | J18: =C30 -> 1.1.4 | K18: =D30 -> Outros Activos Financeiros | L18: =IF(ISERROR($E$30),"",$E$30) -> 0 | M18: =IF(ISERROR(L18/$L$21),"",L18/$L$21) -> 0 | N18: =IF(ISERROR($G$30),"",$G$30) -> 0 | O18: =IF(ISERROR(N18/$N$21),"",N18/$N$21)
C19: 1.1.2.3 | D19: Propriedade industrial e outros direitos e contratos | E19: =Balancete!F38 -> 4887501 | F19: =IF(ISERROR(E19/$E$16),"",E19/$E$16) -> 0.23188911 | G19: =Balancete!G38 -> 0 | J19: =C38 -> 1.1.5 | K19: =D38 -> Provisões para Investimentos Financeiros | L19: =IF(ISERROR($E$38),"",$E$38) -> 0 | M19: =IF(ISERROR(L19/$L$21),"",L19/$L$21) -> 0 | N19: =IF(ISERROR($G$38),"",$G$38) -> 0 | O19: =IF(ISERROR(N19/$N$21),"",N19/$N$21)
C20: 1.1.2.4 | D20: Despesas de constituição | E20: =Balancete!F41 -> 0 | F20: =IF(ISERROR(E20/$E$16),"",E20/$E$16) -> 0 | G20: =Balancete!G41 -> 0 | J20: =C45 -> 1.1.6 | K20: =D45 -> Outros Activos não Correntes | L20: =IF(ISERROR($E$45),"",$E$45) -> 0 | M20: =IF(ISERROR(L20/$L$21),"",L20/$L$21) -> 0 | N20: =IF(ISERROR($G$45),"",$G$45) -> 0 | O20: =IF(ISERROR(N20/$N$21),"",N20/$N$21)
C21: 1.1.2.5 | D21: Outras imobilizações incorpóreas | E21: =Balancete!F42 -> 1.4328832e+08 | F21: =IF(ISERROR(E21/$E$16),"",E21/$E$16) -> 6.7983617 | G21: =Balancete!G42 -> 0 | J21: Total | L21: =IF(ISERROR(SUM($L$15:$L$20)),"",SUM($L$15:$L$20)) -> 3.4449505e+09 | N21: =IF(ISERROR(SUM($N$15:$N$20)),"",SUM($N$15:$N$20)) -> 0
C22: 1.1.2.6 | D22: Adiantamentos por conta de imobilizações incorpóres | E22: =Balancete!F66 -> 0 | F22: =IF(ISERROR(E22/$E$16),"",E22/$E$16) -> 0 | G22: =Balancete!G66 -> 0
C23: 1.1.2.7 | D23: Amortizações acumuladas | E23: =Balancete!F77 -> -2.6080022e+08 | F23: =IF(ISERROR(E23/$E$16),"",E23/$E$16) -> -12.373753 | G23: =Balancete!G77 -> 0 | J23: Valor Total do Ativo Não Corrente
C24: 1.1.2.8 | F24: =IF(ISERROR(E24/$E$16),"",E24/$E$16) -> 0 | J24: Total | L24: =IF(ISERROR(SUM($L$5:$L$13)),"",SUM($L$5:$L$13)) -> 3.4449505e+09 | N24: =IF(ISERROR(SUM($N$5:$N$13)),"",SUM($N$5:$N$13)) -> 0
C25: 1.1.2.9 | F25: =IF(ISERROR(E25/$E$16),"",E25/$E$16) -> 0
C26: 1.1.3 | D26: Investimentos em Subsidiárias e Associadas | E26: =IF(ISERROR(SUM(E27:E29)),"",SUM(E27:E29)) -> 0
C27: 1.1.3.1 | D27: Empresas subsidiárias | E27: =Balancete!F44 -> 0 | F27: =IF(ISERROR(E27/$E$26),"",E27/$E$26) | G27: =Balancete!G44 -> 0
C28: 1.1.3.2 | D28: Empresas associadas | E28: =Balancete!F49 -> 0 | F28: =IF(ISERROR(E28/$E$26),"",E28/$E$26) | G28: =Balancete!G49 -> 0
C29: 1.1.3.3 | F29: =IF(ISERROR(E29/$E$26),"",E29/$E$26)
C30: 1.1.4 | D30: Outros Activos Financeiros | E30: =IF(ISERROR(SUM(E31:E37)),"",SUM(E31:E37)) -> 0
C31: 1.1.4.1 | D31: Investimentos em outras empresas | E31: =Balancete!F55 -> 0 | F31: =IF(ISERROR(E31/$E$30),"",E31/$E$30) | G31: =Balancete!G55 -> 0
C32: 1.1.4.2 | D32: Investimentos em imóveis | E32: =Balancete!F56 -> 0 | F32: =IF(ISERROR(E32/$E$30),"",E32/$E$30) | G32: =Balancete!G56 -> 0
C33: 1.1.4.3 | D33: Fundos - Obrigações | E33: =Balancete!F57 -> 0 | F33: =IF(ISERROR(E33/$E$30),"",E33/$E$30) | G33: =Balancete!G57 -> 0
C34: 1.1.4.4 | D34: Outros investimentos financeiros | E34: =Balancete!F58 -> 0 | F34: =IF(ISERROR(E34/$E$30),"",E34/$E$30) | G34: =Balancete!G58 -> 0
C35: 1.1.4.5 | D35: Adiantamento por conta de investimentos financeiros | E35: =Balancete!F90 -> 0 | F35: =IF(ISERROR(E35/$E$30),"",E35/$E$30) | G35: =Balancete!G90 -> 0
C36: 1.1.4.6 | D36: Amortizações acumuladas - imóveis | E36: =Balancete!F83 -> 0 | F36: =IF(ISERROR(E36/$E$30),"",E36/$E$30) | G36: =Balancete!G83 -> 0
C37: 1.1.4.9 | F37: =IF(ISERROR(E37/$E$30),"",E37/$E$30)
C38: 1.1.5 | D38: Provisões para Investimentos Financeiros | E38: =IF(ISERROR(SUM(E39:E44)),"",SUM(E39:E44)) -> 0
C39: 1.1.5.1 | D39: Empresas subsidiárias | E39: =Balancete!F87 -> 0 | F39: =IF(ISERROR(E39/$E$38),"",E39/$E$38) | G39: =Balancete!G87 -> 0
C40: 1.1.5.2 | D40: Empresas associadas | E40: =Balancete!F88 -> 0 | F40: =IF(ISERROR(E40/$E$38),"",E40/$E$38) | G40: =Balancete!G88 -> 0
C41: 1.1.5.3 | D41: Outras empresas | E41: =Balancete!F89 -> 0 | F41: =IF(ISERROR(E41/$E$38),"",E41/$E$38) | G41: =Balancete!G89 -> 0
...

Sheet Activos Correntes
B2: OBS: NÃO PREENCHER OS CAMPOS EM AZUL. PREENCHIMENTO AUTOMÁTICO.
E3: Ano Corrente | G3: Ano Anterior | L3: Ano Corrente | N3: Ano Anterior
C4: 1.2 | D4: Activos Correntes (Bens e Direitos) | E4: =IF(ISERROR($E$5+$E$15+$E$27+$E$35+$E$50),"",$E$5+$E$15+$E$27+$E$35+$E$50) -> 1.5650931e+09 | G4: =IF(ISERROR($G$5+$G$15+$G$27+$G$35+$G$50),"",$G$5+$G$15+$G$27+$G$35+$G$50) -> 0 | J4: =C4 -> 1.2 | K4: Contas dos Activos Correntes - Total
C5: 1.2.1 | D5: Existências | E5: =IF(ISERROR(SUM(E6:E14)),"",SUM(E6:E14)) -> 0 | G5: =IF(ISERROR(SUM(G6:G14)),"",SUM(G6:G14)) -> 0 | J5: =C5 -> 1.2.1 | K5: =D5 -> Existências | L5: =IF(ISERROR($E$5),"",$E$5) -> 0 | M5: =IF(ISERROR(L5/$P$5),"",L5/$P$5) -> 0 | N5: =IF(ISERROR($G$5),"",$G$5) -> 0 | P5: =IF(ISERROR(SUM($L$5:$L$13)),"",SUM($L$5:$L$13)) -> 1.5650931e+09
C6: 1.2.1.1 | D6: Matérias-primas, subsidiárias e de consumo | E6: =Balancete!F99 -> 0 | F6: =IF(ISERROR(E6/$E$5),"",E6/$E$5) | G6: =Balancete!G99 -> 0 | J6: =C15 -> 1.2.2 | K6: =D15 -> Contas a Receber | L6: =IF(ISERROR($E$15),"",$E$15) -> 1.3402124e+09 | M6: =IF(ISERROR(L6/$P$5),"",L6/$P$5) -> 0.85631482 | N6: =IF(ISERROR($G$15),"",$G$15) -> 0
C7: 1.2.1.2 | D7: Produtos e trabalhos em curso | E7: =Balancete!F105 -> 0 | F7: =IF(ISERROR(E7/$E$5),"",E7/$E$5) | G7: =Balancete!G105 -> 0 | J7: =C27 -> 1.2.3 | K7: =D27 -> Disponibilidades | L7: =IF(ISERROR($E$27),"",$E$27) -> 52657493 | M7: =IF(ISERROR(L7/$P$5),"",L7/$P$5) -> 0.033644958 | N7: =IF(ISERROR($G$27),"",$G$27) -> 0
C8: 1.2.1.3 | D8: Produtos acabados e intermédios | E8: =Balancete!F130 -> 0 | F8: =IF(ISERROR(E8/$E$5),"",E8/$E$5) | G8: =Balancete!G130 -> 0 | J8: =C35 -> 1.2.4 | K8: =D35 -> Outros activos correntes | L8: =IF(ISERROR($E$35),"",$E$35) -> 1.7222319e+08 | M8: =IF(ISERROR(L8/$P$5),"",L8/$P$5) -> 0.11004022 | N8: =IF(ISERROR($G$35),"",$G$35) -> 0
C9: 1.2.1.4 | D9: Subprodutos, desperdícios, resíduos e refugos | E9: =Balancete!F112 -> 0 | F9: =IF(ISERROR(E9/$E$5),"",E9/$E$5) | G9: =Balancete!G112 -> 0 | J9: =C40 -> 1.2.5 | K9: =D40 -> Estado | L9: 0 | M9: =IF(ISERROR(L9/$P$5),"",L9/$P$5) -> 0 | N9: 0
C10: 1.2.1.5 | D10: Mercadorias | E10: =Balancete!F115 -> 0 | F10: =IF(ISERROR(E10/$E$5),"",E10/$E$5) | G10: =Balancete!G115 -> 0 | L10: =IF(ISERROR($E$50),"",$E$50) -> 0 | M10: =IF(ISERROR(L10/$P$5),"",L10/$P$5) -> 0 | N10: =IF(ISERROR($G$50),"",$G$50) -> 0
C11: 1.2.1.6 | D11: Matérias-primas, mercadorias e materiais em trânsito | E11: =Balancete!F119 -> 0 | F11: =IF(ISERROR(E11/$E$5),"",E11/$E$5) | G11: =Balancete!G119 -> 0 | L11: =IF(ISERROR(#REF!),"",#REF!) | M11: =IF(ISERROR(L11/$P$5),"",L11/$P$5) | N11: =IF(ISERROR(#REF!),"",#REF!)
C12: 1.2.1.7 | D12: Adiantamentos por conta de de compras | E12: =Balancete!F123 -> 0 | F12: =IF(ISERROR(E12/$E$5),"",E12/$E$5) | G12: =Balancete!G123 -> 0 | L12: =IF(ISERROR(#REF!),"",#REF!) | M12: =IF(ISERROR(L12/$P$5),"",L12/$P$5) | N12: =IF(ISERROR(#REF!),"",#REF!)
C13: 1.2.1.8 | D13: Provisão para depreciação de existências | E13: =Balancete!F126 -> 0 | F13: =IF(ISERROR(E13/$E$5),"",E13/$E$5) | G13: =Balancete!G126 -> 0 | L13: =IF(ISERROR(#REF!),"",#REF!) | M13: =IF(ISERROR(L13/$P$5),"",L13/$P$5) | N13: =IF(ISERROR(#REF!),"",#REF!)
C14: 1.2.1.9 | F14: =IF(ISERROR(E14/$E$5),"",E14/$E$5)
C15: 1.2.2 | D15: Contas a Receber | E15: =IF(ISERROR(SUM(E16:E26)),"",SUM(E16:E26)) -> 1.3402124e+09 | G15: =IF(ISERROR(SUM(G16:G26)),"",SUM(G16:G26)) -> 0 | J15: Direitos Realizáveis a Curto Prazo
C16: 1.2.2.1 | D16: Clientes-correntes | E16: =Balancete!F135 -> 3.7189837e+08 | F16: =IF(ISERROR(E16/$E$15),"",E16/$E$15) -> 0.2774921 | G16: =Balancete!G135 -> 0 | J16: =J5 -> 1.2.1 | K16: =K5 -> Existências | L16: =IF(ISERROR($E$5),"",$E$5) -> 0 | M16: =IF(ISERROR(L16/$L$19),"",L16/$L$19) -> 0 | N16: =IF(ISERROR($G$5),"",$G$5) -> 0
C17: 1.2.2.2 | D17: Clientes - títulos a receber | E17: =Balancete!F136 -> 0 | F17: =IF(ISERROR(E17/$E$15),"",E17/$E$15) -> 0 | G17: =Balancete!G136 -> 0 | J17: =J6 -> 1.2.2 | K17: =K6 -> Contas a Receber | L17: =IF(ISERROR($E$15),"",$E$15) -> 1.3402124e+09 | M17: =IF(ISERROR(L17/$L$19),"",L17/$L$19) -> 0.96219497 | N17: =IF(ISERROR($G$15),"",$G$15) -> 0
C18: 1.2.2.3 | D18: Clientes de cobrança duvidosa | E18: =Balancete!F138 -> 2.4283678e+08 | F18: =IF(ISERROR(E18/$E$15),"",E18/$E$15) -> 0.18119275 | G18: =Balancete!G138 -> 0 | J18: =J7 -> 1.2.3 | K18: =D27 -> Disponibilidades | L18: =IF(ISERROR($E$27),"",$E$27) -> 52657493 | M18: =IF(ISERROR(L18/$L$19),"",L18/$L$19) -> 0.037805032 | N18: =IF(ISERROR($G$27),"",$G$27) -> 0
C19: 1.2.2.4 | D19: Fornecedores - saldos devedores | E19: =Balancete!F144 -> 2.6343583e+08 | F19: =IF(ISERROR(E19/$E$15),"",E19/$E$15) -> 0.19656274 | G19: =Balancete!G144 -> 0 | J19: Total | L19: =IF(ISERROR(SUM($L$16:$L$18)),"",SUM($L$16:$L$18)) -> 1.3928699e+09 | N19: =IF(ISERROR(SUM($N$16:$N$18)),"",SUM($N$16:$N$18)) -> 0
C20: 1.2.2.5 | D20: Estado | E20: =E40 -> 6.4883625e+08 | F20: =IF(ISERROR(E20/$E$15),"",E20/$E$15) -> 0.4841294 | G20: =G40 -> 0
C21: 1.2.2.6 | D21: Participantes e participadas | E21: =Balancete!F177 -> 0 | F21: =IF(ISERROR(E21/$E$15),"",E21/$E$15) -> 0 | G21: =Balancete!G177 -> 0 | J21: Valor Total do Activo Corrente
C22: 1.2.2.7 | D22: Pessoal | E22: =Balancete!F180 -> 56041998 | F22: =IF(ISERROR(E22/$E$15),"",E22/$E$15) -> 0.041815757 | G22: =Balancete!G190+Balancete!G184 -> 0 | J22: Total | L22: =IF(ISERROR(SUM($L$5:$L$13)),"",SUM($L$5:$L$13)) -> 1.5650931e+09 | N22: =IF(ISERROR(SUM($N$5:$N$13)),"",SUM($N$5:$N$13)) -> 0
C23: 1.2.2.8 | D23: Devedores - venda de imobilizado | E23: =Balancete!F196 -> 0 | F23: =IF(ISERROR(E23/$E$15),"",E23/$E$15) -> 0 | G23: =Balancete!G196 -> 0
C24: 1.2.2.9 | D24: Outros devedores | E24: 0 | F24: =IF(ISERROR(E24/$E$15),"",E24/$E$15) -> 0 | G24: 0
C25: 1.2.2.10 | D25: Provisões para cobrança duvidosa | E25: =Balancete!F226 -> -2.4283678e+08 | F25: =IF(ISERROR(E25/$E$15),"",E25/$E$15) -> -0.18119275 | G25: =Balancete!G226 -> 0
C27: 1.2.3 | D27: Disponibilidades | E27: =IF(ISERROR(SUM(E28:E34)),"",SUM(E28:E34)) -> 52657493 | G27: =IF(ISERROR(SUM(G28:G34)),"",SUM(G28:G34)) -> 0
C28: 1.2.3.1 | D28: Títulos negociáveis | E28: =Balancete!F245 -> 0 | F28: =IF(ISERROR(E28/$E$27),"",E28/$E$27) -> 0 | G28: =Balancete!G245 -> 0
C29: 1.2.3.2 | D29: Saldos em bancos - a prazo | E29: =Balancete!F249 -> 2400000 | F29: =IF(ISERROR(E29/$E$27),"",E29/$E$27) -> 0.045577559 | G29: =Balancete!G249 -> 0
C30: 1.2.3.3 | D30: Saldos em bancos - a ordem | E30: =Balancete!F252 -> 49104474 | F30: =IF(ISERROR(E30/$E$27),"",E30/$E$27) -> 0.93252587 | G30: =Balancete!G252 -> 0
C31: 1.2.3.4 | D31: Caixa | E31: =Balancete!F255 -> 1153018.6 | F31: =IF(ISERROR(E31/$E$27),"",E31/$E$27) -> 0.021896572 | G31: =Balancete!G255 -> 0
C32: 1.2.3.5 | D32: Provisões | E32: =Balancete!F264 -> 0 | F32: =IF(ISERROR(E32/$E$27),"",E32/$E$27) -> 0 | G32: =Balancete!G264 -> 0
C33: 1.2.3.6 | D33: Conta transitória | E33: =Balancete!F261 -> 0 | F33: =IF(ISERROR(E33/$E$27),"",E33/$E$27) -> 0 | G33: =Balancete!G261 -> 0
C34: 1.2.3.7 | F34: =IF(ISERROR(E34/$E$27),"",E34/$E$27) -> 0
C35: 1.2.4 | D35: Outros activos correntes | E35: =IF(ISERROR(SUM(E36:E39)),"",SUM(E36:E39)) -> 1.7222319e+08 | G35: =IF(ISERROR(SUM(G36:G39)),"",SUM(G36:G39)) -> 0 | J35: =
C36: 1.2.4.1 | D36: Outros | E36: =Balancete!F207 -> 1.6523297e+08 | F36: =IF(ISERROR(E36/$E$35),"",E36/$E$35) -> 0.95941188 | G36: 0
C37: 1.2.4.2 | D37: Proveitos a faturar - encargos a repartir por exercícios futuros | F37: =IF(ISERROR(E37/$E$35),"",E37/$E$35) -> 0 | G37: =Balancete!G204 -> 0
C38: 1.2.4.3 | D38: Cartões Visa | E38: =Balancete!F211 -> 6990215 | F38: =IF(ISERROR(E38/$E$35),"",E38/$E$35) -> 0.040588117
C39: 1.2.4.4 | F39: =IF(ISERROR(E39/$E$35),"",E39/$E$35) -> 0
C40: 1.2.5 | D40: Estado | E40: =IF(ISERROR(SUM(E41:E49)),"",SUM(E41:E49)) -> 6.4883625e+08 | G40: =IF(ISERROR(SUM(G41:G49)),"",SUM(G41:G49)) -> 0
D41: Liquidação provisória de imposto industrial | E41: =Balancete!F152 -> 6.4883625e+08 | G41: 0
D42: IVA | E42: =Balancete!F158 -> 0 | G42: =Balancete!G158 -> 0
...

Sheet Capital Próprio
B2: OBS: NÃO PREENCHER OS CAMPOS EM AZUL. PREENCHIMENTO AUTOMÁTICO.
E3: Ano Corrente | G3: Ano Anterior | L3: Ano Corrente | N3: Ano Anterior
C4: 2.1 | D4: Capital Próprio | E4: =IF(ISERROR($E$5+$E$11+$E$17+$E$25+$E$28),"",$E$5+$E$11+$E$17+$E$25+$E$28) -> 3.181566e+09 | G4: =IF(ISERROR($G$5+$G$11+$G$17+$G$25+$G$28),"",$G$5+$G$11+$G$17+$G$25+$G$28) -> 0 | J4: =C4 -> 2.1 | K4: Contas do Capital próprio
C5: 2.1.1 | D5: Capital | E5: =IF(ISERROR(SUM(E6:E10)),"",SUM(E6:E10)) -> 262500000 | G5: =IF(ISERROR(SUM(G6:G10)),"",SUM(G6:G10)) -> 0 | J5: =C5 -> 2.1.1 | K5: =D5 -> Capital | L5: =IF(ISERROR('Capital Próprio'!$E$5),"",'Capital Próprio'!$E$5) -> 262500000 | M5: =IF(ISERROR(L5/$N$5),"",L5/$N$5) | N5: =IF(ISERROR('Capital Próprio'!$G$5),"",'Capital Próprio'!$G$5) -> 0
C6: 2.1.1.1 | D6: Capital | E6: =-Balancete!F268 -> 262500000 | F6: =IF(ISERROR(E6/$E$5),"",E6/$E$5) -> 1 | G6: =-Balancete!G268 -> 0 | J6: =C11 -> 2.1.2 | K6: =D11 -> Reservas | L6: =IF(ISERROR('Capital Próprio'!$E$11),"",'Capital Próprio'!$E$11) -> 0 | M6: =IF(ISERROR(L6/$N$5),"",L6/$N$5) | N6: =IF(ISERROR('Capital Próprio'!$G$11),"",'Capital Próprio'!$G$11) -> 0
C7: 2.1.1.2 | D7: Acções/quotas próprias | E7: =Balancete!F270 -> 0 | F7: =IF(ISERROR(E7/$E$5),"",E7/$E$5) -> 0 | G7: =Balancete!G270 -> 0 | J7: =C17 -> 2.1.3 | K7: =D17 -> Resultados transitados | L7: =IF(ISERROR('Capital Próprio'!$E$17),"",'Capital Próprio'!$E$17) -> 4.5932662e+09 | M7: =IF(ISERROR(L7/$N$5),"",L7/$N$5) | N7: =IF(ISERROR('Capital Próprio'!$G$17),"",'Capital Próprio'!$G$17) -> 0
C8: 2.1.1.3 | D8: Prémios de emissão | E8: =Balancete!F274 -> 0 | F8: =IF(ISERROR(E8/$E$5),"",E8/$E$5) -> 0 | G8: =Balancete!G274 -> 0 | J8: =C25 -> 2.1.4 | K8: =D25 -> Resultados do exercício | L8: =IF(ISERROR('Capital Próprio'!$E$25),"",'Capital Próprio'!$E$25) -> -1.6742002e+09 | M8: =IF(ISERROR(L8/$N$5),"",L8/$N$5) | N8: =IF(ISERROR('Capital Próprio'!$G$25),"",'Capital Próprio'!$G$25) -> 0
C9: 2.1.1.4 | D9: Prestações suplementares | E9: =-Balancete!F276 -> 0 | F9: =IF(ISERROR(E9/$E$5),"",E9/$E$5) -> 0 | G9: =-Balancete!G276 -> 0 | L9: =IF(ISERROR('Capital Próprio'!#REF!),"",'Capital Próprio'!#REF!) | M9: =IF(ISERROR(L9/$N$5),"",L9/$N$5) | N9: =IF(ISERROR('Capital Próprio'!#REF!),"",'Capital Próprio'!#REF!)
C10: 2.1.1.5 | F10: =IF(ISERROR(E10/$E$5),"",E10/$E$5) -> 0 | L10: =IF(ISERROR('Capital Próprio'!#REF!),"",'Capital Próprio'!#REF!) | M10: =IF(ISERROR(L10/$N$5),"",L10/$N$5) | N10: =IF(ISERROR('Capital Próprio'!#REF!),"",'Capital Próprio'!#REF!)
C11: 2.1.2 | D11: Reservas | E11: =IF(ISERROR(SUM(E12:E16)),"",SUM(E12:E16)) -> 0 | G11: =IF(ISERROR(SUM(G12:G16)),"",SUM(G12:G16)) -> 0
C12: 2.1.2.1 | D12: Reserva legal | E12: =-Balancete!F278 -> 0 | F12: =IF(ISERROR(E12/$E$11),"",E12/$E$11) | G12: =-Balancete!G278 -> 0 | J12: Valor Total do Capital Próprio
C13: 2.1.2.2 | D13: Reservas de reavaliação | E13: =Balancete!F282 -> 0 | F13: =IF(ISERROR(E13/$E$11),"",E13/$E$11) | G13: =Balancete!G282 -> 0 | J13: Total | L13: =SUM(L5:L10) -> 3.181566e+09 | N13: =SUM(N5:N10) -> 0
C14: 2.1.2.3 | D14: Reservas com fins especiais | E14: =Balancete!F285 -> 0 | F14: =IF(ISERROR(E14/$E$11),"",E14/$E$11) | G14: =Balancete!G285 -> 0
C15: 2.1.2.4 | D15: Reservas livres | E15: =-Balancete!F287 -> 0 | F15: =IF(ISERROR(E15/$E$11),"",E15/$E$11) | G15: =-Balancete!G287 -> 0
C16: 2.1.2.5 | F16: =IF(ISERROR(E16/$E$11),"",E16/$E$11)
C17: 2.1.3 | D17: Resultados transitados | E17: =IF(ISERROR(SUM(E18:E24)),"",SUM(E18:E24)) -> 4.5932662e+09
C18: 2.1.3.1 | D18: Transferência dos resultados do exercício anterior | E18: =-Balancete!F289 -> 4.5932662e+09 | F18: =IF(ISERROR(E18/$E$17),"",E18/$E$17) -> 1
C19: 2.1.3.2 | D19: Aplicações de resultados | F19: =IF(ISERROR(E19/$E$17),"",E19/$E$17) -> 0
C20: 2.1.3.3 | D20: Erros fundamentais | F20: =IF(ISERROR(E20/$E$17),"",E20/$E$17) -> 0
C21: 2.1.3.4 | D21: Alterações de políticas contabilísticas | F21: =IF(ISERROR(E21/$E$17),"",E21/$E$17) -> 0
C22: 2.1.3.5 | D22: Efeito de impostos dos erros fundamentais e das alterações de políticas contabilísticas | F22: =IF(ISERROR(E22/$E$17),"",E22/$E$17) -> 0
C23: 2.1.3.6 | D23: Outros movimentos | F23: =IF(ISERROR(E23/$E$17),"",E23/$E$17) -> 0
C24: 2.1.3.7 | F24: =IF(ISERROR(E24/$E$17),"",E24/$E$17) -> 0
C25: 2.1.4 | D25: Resultados do exercício | E25: =IF(ISERROR(SUM(E26:E27)),"",SUM(E26:E27)) -> -1.6742002e+09 | G25: =IF(ISERROR(SUM(G26:G27)),"",SUM(G26:G27)) -> 0
C26: 2.1.4.1 | D26: Resultados do exercício | E26: =Balancete!F296 -> -1.6742002e+09 | F26: =IF(ISERROR(E26/$E$25),"",E26/$E$25) -> 1 | G26: =Balancete!G296 -> 0
C27: 2.1.4.2 | F27: =IF(ISERROR(E27/$E$25),"",E27/$E$25) -> 0
C170: 5738 | D170: Debêntures Securitizadas | E170: 467 | F170: =IF(ISERROR(E170/$E$78),"",E170/$E$78)
C171: 5739 | D171: Outros Títulos de Sociedades de Capital de Giro | E171: 45 | F171: =IF(ISERROR(E171/$E$78),"",E171/$E$78)
C172: 5718 | D172: Capital Subscrito a Integralizar | E172: 467 | F172: =IF(ISERROR(E172/$E$68),"",E172/$E$68)
C173: 5719 | D173: Capital Não Subscrito a Realizar | E173: 45 | F173: =IF(ISERROR(E173/$E$68),"",E173/$E$68)

Sheet Passivo Não Corrente
B2: OBS: NÃO PREENCHER OS CAMPOS EM AZUL. PREENCHIMENTO AUTOMÁTICO.
E3: Ano Corrente | G3: Ano Anterior | L3: Ano Corrente | N3: Ano Anterior
C4: 2.2 | D4: Passivo Não Corrente | E4: =IF(ISERROR($E$5+$E$11+$E$21+$E$31+$E$37+$E$41+$E$51),"",$E$5+$E$11+$E$21+$E$31+$E$37+$E$41+$E$51) -> 0 | G4: =IF(ISERROR($G$5+$G$11+$G$21+$G$31+$G$37+$G$41+$G$51),"",$G$5+$G$11+$G$21+$G$31+$G$37+$G$41+$G$51) -> 0 | J4: 2.2 | K4: Contas do Passivo Não Corrente
C5: 2.2.1 | D5: Empréstimos de médio e longo prazos | E5: =IF(ISERROR(SUM(E6:E10)),"",SUM(E6:E10)) -> 0 | G5: =IF(ISERROR(SUM(G6:G10)),"",SUM(G6:G10)) -> 0 | J5: =C5 -> 2.2.1 | K5: =D5 -> Empréstimos de médio e longo prazos | L5: =IF(ISERROR($E$5),"",$E$5) -> 0 | M5: =IF(ISERROR(L5/$N$5),"",L5/$N$5) | N5: =IF(ISERROR($E$5),"",$E$5) -> 0
C6: 2.2.1.1 | D6: Empréstimos bancários | F6: =IF(ISERROR(E6/$E$5),"",E6/$E$5) | J6: =C11 -> 2.2.2 | K6: =D11 -> Impostos diferidos | L6: =IF(ISERROR($E$11),"",$E$11) -> 0 | M6: =IF(ISERROR(L6/$N$5),"",L6/$N$5) | N6: =IF(ISERROR($E$11),"",$E$11) -> 0
C7: 2.2.1.2 | D7: Empréstimos por obrigações | F7: =IF(ISERROR(E7/$E$5),"",E7/$E$5) | J7: =C21 -> 2.2.3 | K7: =D21 -> Provisões para pensões | L7: =IF(ISERROR($E$21),"",$E$21) -> 0 | M7: =IF(ISERROR(L7/$N$5),"",L7/$N$5) | N7: =IF(ISERROR($E$21),"",$E$21) -> 0
C8: 2.2.1.3 | D8: Empréstimos por título de participação | F8: =IF(ISERROR(E8/$E$5),"",E8/$E$5) | J8: =C31 -> 2.2.4 | K8: =D31 -> Provisões para outros riscos e encagos | L8: =IF(ISERROR($E$31),"",$E$31) -> 0 | M8: =IF(ISERROR(L8/$N$5),"",L8/$N$5) | N8: =IF(ISERROR($G$31),"",$G$31) -> 0
C9: 2.2.1.4 | D9: Outros empréstimos | F9: =IF(ISERROR(E9/$E$5),"",E9/$E$5) | J9: =C37 -> 2.2.5 | K9: =D37 -> Outros passivos não correntes | L9: =IF(ISERROR($E$37),"",$E$37) -> 0 | M9: =IF(ISERROR(L9/$N$5),"",L9/$N$5) | N9: =IF(ISERROR($E$37),"",$E$37) -> 0
C10: 2.2.1.5 | F10: =IF(ISERROR(E10/$E$5),"",E10/$E$5) | L10: =IF(ISERROR($E$41),"",$E$41) -> 0 | M10: =IF(ISERROR(L10/$N$5),"",L10/$N$5) | N10: =IF(ISERROR($E$41),"",$E$41) -> 0
C11: 2.2.2 | D11: Impostos diferidos | E11: =IF(ISERROR(SUM(E12:E20)),"",SUM(E12:E20)) -> 0 | G11: =IF(ISERROR(SUM(G12:G20)),"",SUM(G12:G20)) -> 0 | L11: =IF(ISERROR(#REF!),"",#REF!) | M11: =IF(ISERROR(L11/$N$5),"",L11/$N$5) | N11: =IF(ISERROR(#REF!),"",#REF!)
C12: 2.2.2.1 | F12: =IF(ISERROR(E12/$E$11),"",E12/$E$11)
C13: 2.2.2.2 | F13: =IF(ISERROR(E13/$E$11),"",E13/$E$11) | J13: Obrigações Realizáveis a Longo Prazo
C14: 2.2.2.3 | F14: =IF(ISERROR(E14/$E$11),"",E14/$E$11) | J14: =C5 -> 2.2.1 | K14: =D5 -> Empréstimos de médio e longo prazos | L14: =IF(ISERROR($E$5),"",$E$5) -> 0 | M14: =IF(ISERROR(L14/$L$23),"",L14/$L$23)
C15: 2.2.2.4 | F15: =IF(ISERROR(E15/$E$11),"",E15/$E$11) | J15: =C11 -> 2.2.2 | K15: =D11 -> Impostos diferidos | L15: =IF(ISERROR($E$11),"",$E$11) -> 0 | M15: =IF(ISERROR(L15/$L$23),"",L15/$L$23)
C16: 2.2.2.5 | F16: =IF(ISERROR(E16/$E$11),"",E16/$E$11) | J16: =C21 -> 2.2.3 | K16: =D21 -> Provisões para pensões | L16: =IF(ISERROR($E$21),"",$E$21) -> 0 | M16: =IF(ISERROR(L16/$L$23),"",L16/$L$23)
C17: 2.2.2.6 | F17: =IF(ISERROR(E17/$E$11),"",E17/$E$11) | J17: =C31 -> 2.2.4 | K17: =D31 -> Provisões para outros riscos e encagos | L17: =IF(ISERROR($E$31),"",$E$31) -> 0 | M17: =IF(ISERROR(L17/$L$23),"",L17/$L$23) | N17: =IF(ISERROR($G$31),"",$G$31) -> 0
C18: 2.2.2.7 | F18: =IF(ISERROR(E18/$E$11),"",E18/$E$11) | J18: =C37 -> 2.2.5 | K18: =D37 -> Outros passivos não correntes | L18: =IF(ISERROR($E$37),"",$E$37) -> 0 | M18: =IF(ISERROR(L18/$L$23),"",L18/$L$23)
C19: 2.2.2.8 | F19: =IF(ISERROR(E19/$E$11),"",E19/$E$11) | L19: =IF(ISERROR($E$41),"",$E$41) -> 0 | M19: =IF(ISERROR(L19/$L$23),"",L19/$L$23)
C20: 2.2.2.9 | F20: =IF(ISERROR(E20/$E$11),"",E20/$E$11) | L20: =IF(ISERROR($E$51),"",$E$51) -> 0 | M20: =IF(ISERROR(L20/$L$23),"",L20/$L$23)
C21: 2.2.3 | D21: Provisões para pensões | E21: =IF(ISERROR(SUM(E22:E30)),"",SUM(E22:E30)) -> 0 | L21: =IF(ISERROR(#REF!),"",#REF!) | M21: =IF(ISERROR(L21/$L$23),"",L21/$L$23)
C22: 2.2.3.1 | D22: Provisões para pensões | E22: =-Balancete!F239 -> 0 | F22: =IF(ISERROR(E22/$E$21),"",E22/$E$21) | L22: =IF(ISERROR(#REF!),"",#REF!) | M22: =IF(ISERROR(L22/$L$23),"",L22/$L$23)
C23: 2.2.3.2 | F23: =IF(ISERROR(E23/$E$21),"",E23/$E$21) | J23: Total | L23: =IF(ISERROR(SUM($L$14:$L$22)),"",SUM($L$14:$L$22)) -> 0 | N23: =IF(ISERROR(SUM($N$14:$N$22)),"",SUM($N$14:$N$22)) -> 0
C24: 2.2.3.3 | F24: =IF(ISERROR(E24/$E$21),"",E24/$E$21)
C25: 2.2.3.4 | F25: =IF(ISERROR(E25/$E$21),"",E25/$E$21) | J25: Resultado de Exercícios Futuros
C26: 2.2.3.5 | F26: =IF(ISERROR(E26/$E$21),"",E26/$E$21) | L26: =IF(ISERROR(#REF!),"",#REF!) | M26: =IF(ISERROR(L26/$L$28),"",L26/$L$28)
C27: 2.2.3.6 | F27: =IF(ISERROR(E27/$E$21),"",E27/$E$21) | L27: =IF(ISERROR(#REF!),"",#REF!) | M27: =IF(ISERROR(L27/$L$28),"",L27/$L$28)
C28: 2.2.3.7 | F28: =IF(ISERROR(E28/$E$21),"",E28/$E$21) | J28: Total | L28: =IF(ISERROR(SUM($L$26:$L$27)),"",SUM($L$26:$L$27)) -> 0
C29: 2.2.3.8 | F29: =IF(ISERROR(E29/$E$21),"",E29/$E$21)
C30: 2.2.3.9 | F30: =IF(ISERROR(E30/$E$21),"",E30/$E$21) | J30: Valor Total do Passivo Não Corrente
C31: 2.2.4 | D31: Provisões para outros riscos e encagos | E31: =IF(ISERROR(SUM(E32:E36)),"",SUM(E32:E36)) -> 0 | G31: =IF(ISERROR(SUM(G32:G36)),"",SUM(G32:G36)) -> 0 | J31: Total | L31: =IF(ISERROR(SUM($L$5:$L$11)),"",SUM($L$5:$L$11)) -> 0 | N31: =IF(ISERROR(SUM($N$5:$N$11)),"",SUM($N$5:$N$11)) -> 0
C32: 2.2.4.1 | D32: Provisões para processos judiciais em curso | E32: =-Balancete!F240 -> 0 | F32: =IF(ISERROR(E32/$E$31),"",E32/$E$31) | G32: =-Balancete!H240 -> 0
C33: 2.2.4.2 | D33: Provisões para acidentes de trabalho | F33: =IF(ISERROR(E33/$E$31),"",E33/$E$31)
C34: 2.2.4.3 | D34: Provisões para garantias dadas a clientes | F34: =IF(ISERROR(E34/$E$31),"",E34/$E$31)
C35: 2.2.4.4 | D35: Provisões para outros riscos e encargos | E35: =-Balancete!F243 -> 0 | F35: =IF(ISERROR(E35/$E$31),"",E35/$E$31) | G35: =-Balancete!G243 -> 0
C36: 2.2.4.5 | F36: =IF(ISERROR(E36/$E$31),"",E36/$E$31)
C37: 2.2.5 | D37: Outros passivos não correntes | E37: =IF(ISERROR(SUM(E38:E40)),"",SUM(E38:E40)) -> 0
C38: 2.2.5.1 | D38: Subsídio ao investimento - não corrente | E38: =-Balancete!F217 -> 0 | F38: =IF(ISERROR(E38/$E$37),"",E38/$E$37)
C39: 2.2.5.2 | F39: =IF(ISERROR(E39/$E$37),"",E39/$E$37)
C40: 2.2.5.3 | F40: =IF(ISERROR(E40/$E$37),"",E40/$E$37)
C164: 5738 | D164: Debêntures Securitizadas | E164: 467 | F164: =IF(ISERROR(E164/'Capital Próprio'!$E$17),"",E164/'Capital Próprio'!$E$17) -> 1.0167057e-07
...

Sheet Passivo Corrente
B2: OBS: NÃO PREENCHER OS CAMPOS EM AZUL. PREENCHIMENTO AUTOMÁTICO.
E3: Ano Corrente | G3: Ano Anterior | L3: Ano Corrente | N3: Ano Anterior
C4: 2.3 | D4: Passivo Corrente | E4: =IF(ISERROR($E$5+$E$15+$E$25+$E$35+$E$45+$E$55+$E$65),"",$E$5+$E$15+$E$25+$E$35+$E$45+$E$55+$E$65) -> 1.9380363e+09 | G4: =IF(ISERROR($G$5+$G$15+$G$25+$G$35+$G$45+$G$55+$G$65),"",$G$5+$G$15+$G$25+$G$35+$G$45+$G$55+$G$65) -> -2846941.3 | J4: =C4 -> 2.3 | K4: Contas do Passivo Corrente - Total
C5: 2.3.1 | D5: Contas a pagar | E5: =IF(ISERROR(SUM(E6:E14)),"",SUM(E6:E14)) -> 1.006981e+09 | G5: =IF(ISERROR(SUM(G6:G14)),"",SUM(G6:G14)) -> -2553147.2 | J5: =C5 -> 2.3.1 | K5: =D5 -> Contas a pagar | L5: =IF(ISERROR($E$5),"",$E$5) -> 1.006981e+09 | M5: =IF(ISERROR(L5/$N$5),"",L5/$N$5) -> -394.40773 | N5: =IF(ISERROR($G$5),"",$G$5) -> -2553147.2
C6: 2.3.1.1 | D6: Fornecedores - correntes | E6: =-Balancete!F141 -> 2.2780068e+08 | F6: =IF(ISERROR(E6/$E$5),"",E6/$E$5) -> 0.22622143 | G6: =-Balancete!G141 -> 0 | J6: =C15 -> 2.3.2 | K6: =D15 -> Participantes e Participadas | L6: =IF(ISERROR($E$15),"",$E$15) -> 0 | M6: =IF(ISERROR(L6/$N$5),"",L6/$N$5) -> 0 | N6: =IF(ISERROR($G$15),"",$G$15) -> 0
C7: 2.3.1.2 | D7: Fornecedores - títulos a pagar | F7: =IF(ISERROR(E7/$E$5),"",E7/$E$5) -> 0 | J7: =C25 -> 2.3.3 | K7: =D25 -> Pessoal | L7: =IF(ISERROR($E$25),"",$E$25) -> 0 | M7: =IF(ISERROR(L7/$N$5),"",L7/$N$5) -> 0 | N7: =IF(ISERROR($G$25),"",$G$25) -> 0
C8: 2.3.1.3 | D8: Fornecedores - facturas em recepção e conferência | E8: =-Balancete!F143 -> 0 | F8: =IF(ISERROR(E8/$E$5),"",E8/$E$5) -> 0 | G8: =-Balancete!H143 -> 0 | J8: =C35 -> 2.3.4 | K8: =D35 -> Empréstimos de Curto Prazo | L8: =IF(ISERROR($E$35),"",$E$35) -> 0 | M8: =IF(ISERROR(L8/$N$5),"",L8/$N$5) -> 0 | N8: =IF(ISERROR($E$35),"",$E$35) -> 0
C9: 2.3.1.4 | D9: Clientes - saldos credores | E9: =-Balancete!F139 -> 2.9138622e+08 | F9: =IF(ISERROR(E9/$E$5),"",E9/$E$5) -> 0.28936615 | G9: =-Balancete!G139 -> 0 | J9: =C45 -> 2.3.5 | K9: =D45 -> Parte Correspondente dos Empréstimos de Médio e Longo Prazo | L9: =IF(ISERROR($E$45),"",$E$45) -> 0 | M9: =IF(ISERROR(L9/$N$5),"",L9/$N$5) -> 0 | N9: =IF(ISERROR($E$45),"",$E$45) -> 0
C10: 2.3.1.5 | D10: Estado | E10: =E55 -> 4.8779409e+08 | F10: =IF(ISERROR(E10/$E$5),"",E10/$E$5) -> 0.48441241 | G10: =-Balancete!G192 -> 0 | J10: =C55 -> 2.3.6 | K10: =D55 -> Estado | L10: =IF(ISERROR($E$55),"",$E$55) -> 4.8779409e+08 | M10: =IF(ISERROR(L10/$N$5),"",L10/$N$5) -> -191.056 | N10: =IF(ISERROR($G$55),"",G$55) -> 0
C11: 2.3.1.6 | D11: Subsídio de investimento - corrente | F11: =IF(ISERROR(E11/$E$5),"",E11/$E$5) -> 0 | J11: =C65 -> 2.3.7 | K11: =D65 -> Outros Passivos Correntes | L11: =IF(ISERROR($E$65),"",$E$65) -> 4.4326119e+08 | M11: =IF(ISERROR(L11/$N$5),"",L11/$N$5) -> -173.61365 | N11: =IF(ISERROR($G$65),"",$G$65) -> -293794.13
C12: 2.3.1.7 | D12: Outros credores | F12: =IF(ISERROR(E12/$E$5),"",E12/$E$5) -> 0 | G12: -2553147.2 | L12: =IF(ISERROR($E$74),"",$E$74) -> 0 | M12: =IF(ISERROR(L12/$N$5),"",L12/$N$5) -> 0 | N12: =IF(ISERROR($E$74),"",$E$74) -> 0
C13: 2.3.1.8 | F13: =IF(ISERROR(E13/$E$5),"",E13/$E$5) -> 0 | L13: =IF(ISERROR($E$84),"",$E$84) -> 0 | M13: =IF(ISERROR(L13/$N$5),"",L13/$N$5) -> 0 | N13: =IF(ISERROR($E$84),"",$E$84) -> 0
C14: 2.3.1.9 | F14: =IF(ISERROR(E14/$E$5),"",E14/$E$5) -> 0
C15: 2.3.2 | D15: Participantes e Participadas | E15: =IF(ISERROR(SUM(E16:E24)),"",SUM(E16:E24)) -> 0 | G15: =IF(ISERROR(SUM(G16:G24)),"",SUM(G16:G24)) -> 0 | J15: Obrigações Realizáveis a Curto Prazo
C16: 2.3.2.1 | D16: Entidades participantes | E16: 0 | F16: =IF(ISERROR(E16/$E$15),"",E16/$E$15) | J16: =C5 -> 2.3.1 | K16: =D5 -> Contas a pagar | L16: =IF(ISERROR($E$5),"",$E$5) -> 1.006981e+09 | M16: =IF(ISERROR(L16/$L$19),"",L16/$L$19) -> 2.0643567 | N16: =IF(ISERROR($G$5),"",$G$5) -> -2553147.2
C17: 2.3.2.2 | D17: Entidades participadas | F17: =IF(ISERROR(E17/$E$15),"",E17/$E$15) | J17: =C15 -> 2.3.2 | K17: =D15 -> Participantes e Participadas | L17: =IF(ISERROR($E$15),"",$E$15) -> 0 | M17: =IF(ISERROR(L17/$L$19),"",L17/$L$19) -> 0 | N17: =IF(ISERROR($G$15),"",$G$15) -> 0
C18: 2.3.2.3 | F18: =IF(ISERROR(E18/$E$15),"",E18/$E$15) | J18: =C25 -> 2.3.3 | K18: =D25 -> Pessoal | L18: =IF(ISERROR($E$25),"",$E$25) -> 0 | M18: =IF(ISERROR(L18/$L$19),"",L18/$L$19) -> 0 | N18: =IF(ISERROR($G$25),"",$G$25) -> 0
C19: 2.3.2.4 | F19: =IF(ISERROR(E19/$E$15),"",E19/$E$15) | J19: =C55 -> 2.3.6 | K19: =D55 -> Estado | L19: =IF(ISERROR($E$55),"",$E$55) -> 4.8779409e+08 | M19: =IF(ISERROR(L19/$L$19),"",L19/$L$19) -> 1 | N19: =IF(ISERROR($E$35),"",$E$35) -> 0
C20: 2.3.2.5 | F20: =IF(ISERROR(E20/$E$15),"",E20/$E$15) | J20: =C45 -> 2.3.5 | K20: =D45 -> Parte Correspondente dos Empréstimos de Médio e Longo Prazo | L20: =IF(ISERROR($E$45),"",$E$45) -> 0 | M20: =IF(ISERROR(L20/$L$19),"",L20/$L$19) -> 0 | N20: =IF(ISERROR($E$45),"",$E$45) -> 0
C21: 2.3.2.6 | F21: =IF(ISERROR(E21/$E$15),"",E21/$E$15) | M21: =IF(ISERROR(L21/$L$19),"",L21/$L$19) -> 0
C22: 2.3.2.7 | F22: =IF(ISERROR(E22/$E$15),"",E22/$E$15) | J22: Total | L22: =IF(ISERROR(SUM($L$16:$L$21)),"",SUM($L$16:$L$21)) -> 1.4947751e+09 | N22: =IF(ISERROR(SUM($N$16:$N$21)),"",SUM($N$16:$N$21)) -> -2553147.2
C23: 2.3.2.8 | F23: =IF(ISERROR(E23/$E$15),"",E23/$E$15)
C24: 2.3.2.9 | F24: =IF(ISERROR(E24/$E$15),"",E24/$E$15) | J24: Valor Total do Passivo Circulante
C25: 2.3.3 | D25: Pessoal | E25: =IF(ISERROR(SUM(E26:E34)),"",SUM(E26:E34)) -> 0 | G25: =-IF(ISERROR(SUM(G26:G34)),"",SUM(G26:G34)) -> 0 | J25: Total | L25: =IF(ISERROR(SUM($L$5:$L$13)),"",SUM($L$5:$L$13)) -> 1.9380363e+09 | N25: =IF(ISERROR(SUM($N$5:$N$13)),"",SUM($N$5:$N$13)) -> -2846941.3
C26: 2.3.3.1 | D26: Pessoal - remunerações | E26: =-Balancete!F181 -> 0 | F26: =IF(ISERROR(E26/$E$25),"",E26/$E$25) | G26: =-Balancete!G181 -> 0
C27: 2.3.3.2 | D27: Pessoal - Participação nos resultados | F27: =IF(ISERROR(E27/$E$25),"",E27/$E$25)
C28: 2.3.3.3 | D28: Pessoal - adiantamentos | F28: =IF(ISERROR(E28/$E$25),"",E28/$E$25) | G28: =-Balancete!G187 -> 0 | L28: =G4-313116786.31 -> -3.1596373e+08
C29: 2.3.3.4 | D29: Pessoal - Outros | F29: =IF(ISERROR(E29/$E$25),"",E29/$E$25)
C30: 2.3.3.5 | F30: =IF(ISERROR(E30/$E$25),"",E30/$E$25)
C31: 2.3.3.6 | F31: =IF(ISERROR(E31/$E$25),"",E31/$E$25)
C32: 2.3.3.7 | F32: =IF(ISERROR(E32/$E$25),"",E32/$E$25)
C33: 2.3.3.8 | F33: =IF(ISERROR(E33/$E$25),"",E33/$E$25)
C34: 2.3.3.9 | F34: =IF(ISERROR(E34/$E$25),"",E34/$E$25)
C35: 2.3.4 | D35: Empréstimos de Curto Prazo | E35: =IF(ISERROR(SUM(E36:E44)),"",SUM(E36:E44)) -> 0
C36: 2.3.4.1 | D36: Empréstimos bancários | F36: =IF(ISERROR(E36/$E$35),"",E36/$E$35)
C37: 2.3.4.2 | D37: Empréstimos por obrigações | F37: =IF(ISERROR(E37/$E$35),"",E37/$E$35)
C38: 2.3.4.3 | D38: Empréstimo por título de participação | F38: =IF(ISERROR(E38/$E$35),"",E38/$E$35)
C39: 2.3.4.4 | D39: Outros empréstimos | F39: =IF(ISERROR(E39/$E$35),"",E39/$E$35)
C40: 2.3.4.5 | F40: =IF(ISERROR(E40/$E$35),"",E40/$E$35)
C41: 2.3.4.6 | F41: =IF(ISERROR(E41/$E$35),"",E41/$E$35)
...

Sheet Balanço Patrimonial
B2: OBS: PLANILHA AUTOMÁTICA. NÃO PREENCHER NENHUM CAMPO.
C4: ='Activos Não Correntes'!C4 -> 1.1 | D4: Contas do Activo Não Corrente | E4: Ano Corrente | G4: Ano Anterior | J4: ='Passivo Não Corrente'!J4 -> 2.2 | K4: Contas do Passivo Não Corrente | L4: Ano Corrente | N4: Ano Anterior
C5: ='Activos Não Correntes'!C5 -> 1.1.1 | D5: ='Activos Não Correntes'!D5 -> Imobilizações corpóreas | E5: =IF(ISERROR('Activos Não Correntes'!L5),"",'Activos Não Correntes'!L5) -> 3.4238736e+09 | F5: =IF(ISERROR('Activos Não Correntes'!M5),"",'Activos Não Correntes'!M5) -> 0.9938818 | G5: =IF(ISERROR('Activos Não Correntes'!N5),"",'Activos Não Correntes'!N5) -> 0 | J5: ='Passivo Não Corrente'!J5 -> 2.2.1 | K5: ='Passivo Não Corrente'!K5 -> Empréstimos de médio e longo prazos | L5: =IF(ISERROR('Passivo Não Corrente'!L5),"",'Passivo Não Corrente'!L5) -> 0 | M5: =IF(ISERROR('Passivo Não Corrente'!M5),"",'Passivo Não Corrente'!M5) | N5: =IF(ISERROR('Passivo Não Corrente'!N5),"",'Passivo Não Corrente'!N5) -> 0
C6: ='Activos Não Correntes'!C16 -> 1.1.2 | D6: ='Activos Não Correntes'!D16 -> Imobilizações incorpóreas | E6: =IF(ISERROR('Activos Não Correntes'!L6),"",'Activos Não Correntes'!L6) -> 21076889 | F6: =IF(ISERROR('Activos Não Correntes'!M6),"",'Activos Não Correntes'!M6) -> 0.0061181981 | G6: =IF(ISERROR('Activos Não Correntes'!N6),"",'Activos Não Correntes'!N6) -> 0 | J6: ='Passivo Não Corrente'!J6 -> 2.2.2 | K6: ='Passivo Não Corrente'!K6 -> Impostos diferidos | L6: =IF(ISERROR('Passivo Não Corrente'!L6),"",'Passivo Não Corrente'!L6) -> 0 | M6: =IF(ISERROR('Passivo Não Corrente'!M6),"",'Passivo Não Corrente'!M6) | N6: =IF(ISERROR('Passivo Não Corrente'!N6),"",'Passivo Não Corrente'!N6) -> 0
C7: ='Activos Não Correntes'!C26 -> 1.1.3 | D7: ='Activos Não Correntes'!D26 -> Investimentos em Subsidiárias e Associadas | E7: =IF(ISERROR('Activos Não Correntes'!L7),"",'Activos Não Correntes'!L7) -> 0 | F7: =IF(ISERROR('Activos Não Correntes'!M7),"",'Activos Não Correntes'!M7) -> 0 | G7: =IF(ISERROR('Activos Não Correntes'!N7),"",'Activos Não Correntes'!N7) -> 0 | J7: ='Passivo Não Corrente'!J7 -> 2.2.3 | K7: ='Passivo Não Corrente'!K7 -> Provisões para pensões | L7: =IF(ISERROR('Passivo Não Corrente'!L7),"",'Passivo Não Corrente'!L7) -> 0 | M7: =IF(ISERROR('Passivo Não Corrente'!M7),"",'Passivo Não Corrente'!M7) | N7: =IF(ISERROR('Passivo Não Corrente'!N7),"",'Passivo Não Corrente'!N7) -> 0
C8: ='Activos Não Correntes'!C30 -> 1.1.4 | D8: ='Activos Não Correntes'!D30 -> Outros Activos Financeiros | E8: =IF(ISERROR('Activos Não Correntes'!L8),"",'Activos Não Correntes'!L8) -> 0 | F8: =IF(ISERROR('Activos Não Correntes'!M8),"",'Activos Não Correntes'!M8) -> 0 | G8: =IF(ISERROR('Activos Não Correntes'!N8),"",'Activos Não Correntes'!N8) -> 0 | J8: ='Passivo Não Corrente'!J8 -> 2.2.4 | K8: ='Passivo Não Corrente'!K8 -> Provisões para outros riscos e encagos | L8: =IF(ISERROR('Passivo Não Corrente'!L8),"",'Passivo Não Corrente'!L8) -> 0 | M8: =IF(ISERROR('Passivo Não Corrente'!M8),"",'Passivo Não Corrente'!M8) | N8: =IF(ISERROR('Passivo Não Corrente'!N8),"",'Passivo Não Corrente'!N8) -> 0
C9: ='Activos Não Correntes'!C38 -> 1.1.5 | D9: ='Activos Não Correntes'!D38 -> Provisões para Investimentos Financeiros | E9: =IF(ISERROR('Activos Não Correntes'!L9),"",'Activos Não Correntes'!L9) -> 0 | F9: =IF(ISERROR('Activos Não Correntes'!M9),"",'Activos Não Correntes'!M9) -> 0 | G9: =IF(ISERROR('Activos Não Correntes'!N9),"",'Activos Não Correntes'!N9) -> 0 | J9: ='Passivo Não Corrente'!J9 -> 2.2.5 | K9: ='Passivo Não Corrente'!K9 -> Outros passivos não correntes | L9: =IF(ISERROR('Passivo Não Corrente'!L9),"",'Passivo Não Corrente'!L9) -> 0 | M9: =IF(ISERROR('Passivo Não Corrente'!M9),"",'Passivo Não Corrente'!M9) | N9: =IF(ISERROR('Passivo Não Corrente'!N9),"",'Passivo Não Corrente'!N9) -> 0
C10: ='Activos Não Correntes'!C45 -> 1.1.6 | D10: ='Activos Não Correntes'!D45 -> Outros Activos não Correntes | E10: =IF(ISERROR('Activos Não Correntes'!L20),"",'Activos Não Correntes'!L20) -> 0 | F10: =IF(ISERROR('Activos Não Correntes'!#REF!),"",'Activos Não Correntes'!#REF!) | G10: =IF(ISERROR('Activos Não Correntes'!N20),"",'Activos Não Correntes'!N20) -> 0 | J10: 0 | K10: 0 | L10: =IF(ISERROR('Passivo Não Corrente'!L10),"",'Passivo Não Corrente'!L10) -> 0 | M10: =IF(ISERROR('Passivo Não Corrente'!M10),"",'Passivo Não Corrente'!M10) | N10: =IF(ISERROR('Passivo Não Corrente'!N10),"",'Passivo Não Corrente'!N10) -> 0
C11: ='Activos Não Correntes'!C55 -> 0 | D11: ='Activos Não Correntes'!D55 -> 0 | E11: =IF(ISERROR('Activos Não Correntes'!L11),"",'Activos Não Correntes'!L11) -> 0 | F11: =IF(ISERROR('Activos Não Correntes'!M11),"",'Activos Não Correntes'!M11) -> 0 | G11: =IF(ISERROR('Activos Não Correntes'!N11),"",'Activos Não Correntes'!N11) -> 0 | J11: 0 | K11: 0 | L11: =IF(ISERROR('Passivo Não Corrente'!#REF!),"",'Passivo Não Corrente'!#REF!) | M11: =IF(ISERROR('Passivo Não Corrente'!#REF!),"",'Passivo Não Corrente'!#REF!) | N11: =IF(ISERROR('Passivo Não Corrente'!#REF!),"",'Passivo Não Corrente'!#REF!)
C12: ='Activos Correntes'!J12 -> 0 | D12: ='Activos Correntes'!K12 -> 0 | E12: =IF(ISERROR('Activos Não Correntes'!L12),"",'Activos Não Correntes'!L12) -> 0 | F12: =IF(ISERROR('Activos Não Correntes'!M12),"",'Activos Não Correntes'!M12) -> 0 | G12: =IF(ISERROR('Activos Não Correntes'!N12),"",'Activos Não Correntes'!N12) -> 0 | J12: ='Passivo Corrente'!J12 -> 0 | K12: ='Passivo Corrente'!K12 -> 0 | L12: =IF(ISERROR('Passivo Não Corrente'!#REF!),"",'Passivo Não Corrente'!#REF!) | M12: =IF(ISERROR('Passivo Não Corrente'!#REF!),"",'Passivo Não Corrente'!#REF!) | N12: =IF(ISERROR('Passivo Não Corrente'!#REF!),"",'Passivo Não Corrente'!#REF!)
C13: ='Activos Correntes'!J13 -> 0 | D13: ='Activos Correntes'!K13 -> 0 | E13: =IF(ISERROR('Activos Não Correntes'!L13),"",'Activos Não Correntes'!L13) -> 0 | F13: =IF(ISERROR('Activos Não Correntes'!M13),"",'Activos Não Correntes'!M13) -> 0 | G13: =IF(ISERROR('Activos Não Correntes'!N13),"",'Activos Não Correntes'!N13) -> 0 | J13: ='Passivo Corrente'!J13 -> 0 | K13: ='Passivo Corrente'!K13 -> 0 | L13: =IF(ISERROR('Passivo Não Corrente'!#REF!),"",'Passivo Não Corrente'!#REF!) | M13: =IF(ISERROR('Passivo Não Corrente'!#REF!),"",'Passivo Não Corrente'!#REF!) | N13: =IF(ISERROR('Passivo Não Corrente'!#REF!),"",'Passivo Não Corrente'!#REF!)
C14: Total | E14: =IF(ISERROR(SUM(E5:E13)),"",SUM(E5:E13)) -> 3.4449505e+09 | G14: =IF(ISERROR(SUM(G5:G13)),"",SUM(G5:G13)) -> 0 | J14: Total | L14: =IF(ISERROR(SUM(L5:L13)),"",SUM(L5:L13)) -> 0 | N14: =IF(ISERROR(SUM(N5:N13)),"",SUM(N5:N13)) -> 0
C15: Total apresentado pela entidade | E15: 3.4449505e+09 | G15: 1.8696976e+08 | J15: Total apresentado pela entidade | L15: 0 | N15: 52083465
C16: Diferença | E16: =E14-E15 -> 0 | G16: =G14-G15 -> -1.8696976e+08 | J16: Diferença | L16: =L14-L15 -> 0 | N16: =N14-N15 -> -52083465
C18: ='Activos Correntes'!C4 -> 1.2 | D18: Contas do Activo Corrente | J18: ='Passivo Corrente'!J4 -> 2.3 | K18: Contas do Passivo Corrente | L18: Ano Corrente | N18: Ano Anterior
C19: ='Activos Correntes'!C5 -> 1.2.1 | D19: ='Activos Correntes'!D5 -> Existências | E19: =IF(ISERROR('Activos Correntes'!L5),"",'Activos Correntes'!L5) -> 0 | F19: =IF(ISERROR('Activos Correntes'!M5),"",'Activos Correntes'!M5) -> 0 | G19: =IF(ISERROR('Activos Correntes'!N5),"",'Activos Correntes'!N5) -> 0 | J19: ='Passivo Corrente'!J5 -> 2.3.1 | K19: ='Passivo Corrente'!K5 -> Contas a pagar | L19: =IF(ISERROR('Passivo Corrente'!L5),"",'Passivo Corrente'!L5) -> 1.006981e+09 | M19: =IF(ISERROR('Passivo Não Corrente'!M5),"",'Passivo Não Corrente'!M5) | N19: =IF(ISERROR('Passivo Corrente'!N5),"",'Passivo Corrente'!N5) -> -2553147.2
C20: ='Activos Correntes'!C15 -> 1.2.2 | D20: ='Activos Correntes'!D15 -> Contas a Receber | E20: =IF(ISERROR('Activos Correntes'!L6),"",'Activos Correntes'!L6) -> 1.3402124e+09 | F20: =IF(ISERROR('Activos Correntes'!M6),"",'Activos Correntes'!M6) -> 0.85631482 | G20: =IF(ISERROR('Activos Correntes'!N6),"",'Activos Correntes'!N6) -> 0 | J20: ='Passivo Corrente'!J6 -> 2.3.2 | K20: ='Passivo Corrente'!K6 -> Participantes e Participadas | L20: =IF(ISERROR('Passivo Corrente'!L6),"",'Passivo Corrente'!L6) -> 0 | M20: =IF(ISERROR('Passivo Não Corrente'!M6),"",'Passivo Não Corrente'!M6) | N20: =IF(ISERROR('Passivo Corrente'!N6),"",'Passivo Corrente'!N6) -> 0
C21: ='Activos Correntes'!C27 -> 1.2.3 | D21: ='Activos Correntes'!D27 -> Disponibilidades | E21: =IF(ISERROR('Activos Correntes'!L7),"",'Activos Correntes'!L7) -> 52657493 | F21: =IF(ISERROR('Activos Correntes'!M7),"",'Activos Correntes'!M7) -> 0.033644958 | G21: =IF(ISERROR('Activos Correntes'!N7),"",'Activos Correntes'!N7) -> 0 | J21: ='Passivo Corrente'!J7 -> 2.3.3 | K21: ='Passivo Corrente'!K7 -> Pessoal | L21: =IF(ISERROR('Passivo Corrente'!L7),"",'Passivo Corrente'!L7) -> 0 | M21: =IF(ISERROR('Passivo Não Corrente'!M7),"",'Passivo Não Corrente'!M7) | N21: =IF(ISERROR('Passivo Corrente'!N7),"",'Passivo Corrente'!N7) -> 0
C22: ='Activos Correntes'!C35 -> 1.2.4 | D22: ='Activos Correntes'!D35 -> Outros activos correntes | E22: =IF(ISERROR('Activos Correntes'!L8),"",'Activos Correntes'!L8) -> 1.7222319e+08 | F22: =IF(ISERROR('Activos Correntes'!M8),"",'Activos Correntes'!M8) -> 0.11004022 | G22: =IF(ISERROR('Activos Correntes'!N8),"",'Activos Correntes'!N8) -> 0 | J22: ='Passivo Corrente'!J8 -> 2.3.4 | K22: ='Passivo Corrente'!K8 -> Empréstimos de Curto Prazo | L22: =IF(ISERROR('Passivo Corrente'!L8),"",'Passivo Corrente'!L8) -> 0 | M22: =IF(ISERROR('Passivo Não Corrente'!M8),"",'Passivo Não Corrente'!M8) | N22: =IF(ISERROR('Passivo Corrente'!N8),"",'Passivo Corrente'!N8) -> 0
C23: ='Activos Correntes'!C40 -> 1.2.5 | D23: ='Activos Correntes'!D40 -> Estado | E23: =IF(ISERROR('Activos Correntes'!L9),"",'Activos Correntes'!L9) -> 0 | F23: =IF(ISERROR('Activos Correntes'!M9),"",'Activos Correntes'!M9) -> 0 | G23: =IF(ISERROR('Activos Correntes'!N9),"",'Activos Correntes'!N9) -> 0 | J23: ='Passivo Corrente'!J9 -> 2.3.5 | K23: ='Passivo Corrente'!K9 -> Parte Correspondente dos Empréstimos de Médio e Longo Prazo | L23: =IF(ISERROR('Passivo Corrente'!L9),"",'Passivo Corrente'!L9) -> 0 | M23: =IF(ISERROR('Passivo Não Corrente'!M9),"",'Passivo Não Corrente'!M9) | N23: =IF(ISERROR('Passivo Corrente'!N9),"",'Passivo Corrente'!N9) -> 0
C24: ='Activos Correntes'!C50 -> 0 | D24: ='Activos Correntes'!D50 -> 0 | E24: =IF(ISERROR('Activos Correntes'!L10),"",'Activos Correntes'!L10) -> 0 | F24: =IF(ISERROR('Activos Correntes'!M10),"",'Activos Correntes'!M10) -> 0 | G24: =IF(ISERROR('Activos Correntes'!N10),"",'Activos Correntes'!N10) -> 0 | J24: ='Passivo Corrente'!J10 -> 2.3.6 | K24: ='Passivo Corrente'!K10 -> Estado | L24: =IF(ISERROR('Passivo Corrente'!L10),"",'Passivo Corrente'!L10) -> 4.8779409e+08 | M24: =IF(ISERROR('Passivo Não Corrente'!M10),"",'Passivo Não Corrente'!M10) | N24: =IF(ISERROR('Passivo Corrente'!N10),"",'Passivo Corrente'!N10) -> 0
J25: ='Passivo Corrente'!J11 -> 2.3.7 | K25: ='Passivo Corrente'!K11 -> Outros Passivos Correntes | L25: =IF(ISERROR('Passivo Corrente'!L11),"",'Passivo Corrente'!L11) -> 4.4326119e+08 | M25: =IF(ISERROR('Passivo Não Corrente'!#REF!),"",'Passivo Não Corrente'!#REF!) | N25: =IF(ISERROR('Passivo Corrente'!N11),"",'Passivo Corrente'!N11) -> -293794.13
J26: Total | L26: =IF(ISERROR(SUM(L19:L25)),"",SUM(L19:L25)) -> 1.9380363e+09 | N26: =IF(ISERROR(SUM(N19:N25)),"",SUM(N19:N25)) -> -2846941.3
J27: Total apresentado pela entidade | L27: 1828476000 | N27: 3.1311679e+08
J28: Diferença | L28: =L26-L27 -> 1.0956028e+08 | N28: =N26-N27 -> -3.1596373e+08
J30: ='Capital Próprio'!J4 -> 2.1 | K30: Contas do Capital Próprio | L30: Ano Corrente | N30: Ano Anterior
J31: ='Capital Próprio'!J5 -> 2.1.1 | K31: ='Capital Próprio'!K5 -> Capital | L31: =IF(ISERROR('Capital Próprio'!L5),"",'Capital Próprio'!L5) -> 262500000 | M31: =IF(ISERROR('Capital Próprio'!M5),"",'Capital Próprio'!M5) | N31: =IF(ISERROR('Capital Próprio'!N5),"",'Capital Próprio'!N5) -> 0
C32: Total | E32: =IF(ISERROR(SUM(E19:E31)),"",SUM(E19:E31)) -> 1.5650931e+09 | G32: =IF(ISERROR(SUM(G19:G31)),"",SUM(G19:G31)) -> 0 | J32: ='Capital Próprio'!J6 -> 2.1.2 | K32: ='Capital Próprio'!K6 -> Reservas | L32: =IF(ISERROR('Capital Próprio'!L6),"",'Capital Próprio'!L6) -> 0 | M32: =IF(ISERROR('Capital Próprio'!M6),"",'Capital Próprio'!M6) | N32: =IF(ISERROR('Capital Próprio'!N6),"",'Capital Próprio'!N6) -> 0
C33: Total apresentado pela entidade | E33: 1.5650931e+09 | G33: 8.3966785e+08 | J33: ='Capital Próprio'!J7 -> 2.1.3 | K33: ='Capital Próprio'!K7 -> Resultados transitados | L33: =IF(ISERROR('Capital Próprio'!L7),"",'Capital Próprio'!L7) -> 4.5932662e+09 | M33: =IF(ISERROR('Capital Próprio'!M7),"",'Capital Próprio'!M7) | N33: =IF(ISERROR('Capital Próprio'!N7),"",'Capital Próprio'!N7) -> 0
C34: Diferença | E34: =E32-E33 -> 0 | G34: =G32-G33 -> -8.3966785e+08 | J34: ='Capital Próprio'!J8 -> 2.1.4 | K34: ='Capital Próprio'!K8 -> Resultados do exercício | L34: =IF(ISERROR('Capital Próprio'!L8),"",'Capital Próprio'!L8) -> -1.6742002e+09 | M34: =IF(ISERROR('Capital Próprio'!M8),"",'Capital Próprio'!M8) | N34: =IF(ISERROR('Capital Próprio'!N8),"",'Capital Próprio'!N8) -> 0
L35: =IF(ISERROR('Capital Próprio'!L9),"",'Capital Próprio'!L9) | M35: =IF(ISERROR('Capital Próprio'!M9),"",'Capital Próprio'!M9)
C36: Total do Balanço Patrimonial | J36: Total | L36: =IF(ISERROR(SUM(L31:L35)),"",SUM(L31:L35)) -> 3.181566e+09 | N36: =IF(ISERROR(SUM(N31:N35)),"",SUM(N31:N35)) -> 0
C37: Activo | E37: =IF(ISERROR(E14+E32),"",E14+E32) -> 5.0100436e+09 | G37: =IF(ISERROR(G14+G32),"",G14+G32) -> 0 | J37: Total apresentado pela entidade | L37: 3.181566e+09 | N37: 6.6143736e+08
